<?xml version="1.0" encoding="UTF-8"?>
<!-- Generated by org.testng.reporters.JUnitReportReporter -->
<testsuite hostname="LAPTOP-8QE8IR6F" failures="5" tests="12" name="TestNG.HardAssertEx" time="0.032" errors="0" timestamp="2024-12-06T14:20:26 IST" skipped="1">
  <testcase classname="TestNG.HardAssertEx" name="m1" time="0.019">
    <failure message="expected [true] but found [false]" type="java.lang.AssertionError">
      <![CDATA[java.lang.AssertionError: expected [true] but found [false]
at org.testng.Assert.fail(Assert.java:99)
at org.testng.Assert.failNotEquals(Assert.java:1037)
at org.testng.Assert.assertEqualsImpl(Assert.java:140)
at org.testng.Assert.assertEquals(Assert.java:122)
at org.testng.Assert.assertEquals(Assert.java:819)
at org.testng.Assert.assertEquals(Assert.java:829)
at TestNG.HardAssertEx.m1(HardAssertEx.java:12)
at java.base/jdk.internal.reflect.DirectMethodHandleAccessor.invoke(DirectMethodHandleAccessor.java:103)
at java.base/java.lang.reflect.Method.invoke(Method.java:580)
at org.testng.internal.MethodInvocationHelper.invokeMethod(MethodInvocationHelper.java:133)
at org.testng.internal.TestInvoker.invokeMethod(TestInvoker.java:598)
at org.testng.internal.TestInvoker.invokeTestMethod(TestInvoker.java:173)
at org.testng.internal.MethodRunner.runInSequence(MethodRunner.java:46)
at org.testng.internal.TestInvoker$MethodInvocationAgent.invoke(TestInvoker.java:824)
at org.testng.internal.TestInvoker.invokeTestMethods(TestInvoker.java:146)
at org.testng.internal.TestMethodWorker.invokeTestMethods(TestMethodWorker.java:146)
at org.testng.internal.TestMethodWorker.run(TestMethodWorker.java:128)
at java.base/java.util.ArrayList.forEach(ArrayList.java:1596)
at org.testng.TestRunner.privateRun(TestRunner.java:794)
at org.testng.TestRunner.run(TestRunner.java:596)
at org.testng.SuiteRunner.runTest(SuiteRunner.java:377)
at org.testng.SuiteRunner.runSequentially(SuiteRunner.java:371)
at org.testng.SuiteRunner.privateRun(SuiteRunner.java:332)
at org.testng.SuiteRunner.run(SuiteRunner.java:276)
at org.testng.SuiteRunnerWorker.runSuite(SuiteRunnerWorker.java:53)
at org.testng.SuiteRunnerWorker.run(SuiteRunnerWorker.java:96)
at org.testng.TestNG.runSuitesSequentially(TestNG.java:1212)
at org.testng.TestNG.runSuitesLocally(TestNG.java:1134)
at org.testng.TestNG.runSuites(TestNG.java:1063)
at org.testng.TestNG.run(TestNG.java:1031)
at org.testng.remote.AbstractRemoteTestNG.run(AbstractRemoteTestNG.java:115)
at org.testng.remote.RemoteTestNG.initAndRun(RemoteTestNG.java:293)
at org.testng.remote.RemoteTestNG.main(RemoteTestNG.java:91)
]]>
    </failure>
  </testcase> <!-- m1 -->
  <system-out/>
  <testcase classname="TestNG.HardAssertEx" name="m5" time="0.002"/>
  <system-out/>
  <testcase classname="TestNG.HardAssertEx" name="m2" time="0.001"/>
  <system-out/>
  <testcase classname="TestNG.HardAssertEx" name="m9" time="0.002"/>
  <system-out/>
  <testcase classname="TestNG.HardAssertEx" name="m3" time="0.001"/>
  <system-out/>
  <testcase classname="TestNG.HardAssertEx" name="m11" time="0.001"/>
  <system-out/>
  <testcase classname="TestNG.HardAssertEx" name="m6" time="0.001">
    <failure message="True expected [false] but found [true]" type="java.lang.AssertionError">
      <![CDATA[java.lang.AssertionError: True expected [false] but found [true]
at org.testng.Assert.fail(Assert.java:99)
at org.testng.Assert.failNotEquals(Assert.java:1037)
at org.testng.Assert.assertFalse(Assert.java:67)
at TestNG.HardAssertEx.m6(HardAssertEx.java:52)
at java.base/jdk.internal.reflect.DirectMethodHandleAccessor.invoke(DirectMethodHandleAccessor.java:103)
at java.base/java.lang.reflect.Method.invoke(Method.java:580)
at org.testng.internal.MethodInvocationHelper.invokeMethod(MethodInvocationHelper.java:133)
at org.testng.internal.TestInvoker.invokeMethod(TestInvoker.java:598)
at org.testng.internal.TestInvoker.invokeTestMethod(TestInvoker.java:173)
at org.testng.internal.MethodRunner.runInSequence(MethodRunner.java:46)
at org.testng.internal.TestInvoker$MethodInvocationAgent.invoke(TestInvoker.java:824)
at org.testng.internal.TestInvoker.invokeTestMethods(TestInvoker.java:146)
at org.testng.internal.TestMethodWorker.invokeTestMethods(TestMethodWorker.java:146)
at org.testng.internal.TestMethodWorker.run(TestMethodWorker.java:128)
at java.base/java.util.ArrayList.forEach(ArrayList.java:1596)
at org.testng.TestRunner.privateRun(TestRunner.java:794)
at org.testng.TestRunner.run(TestRunner.java:596)
at org.testng.SuiteRunner.runTest(SuiteRunner.java:377)
at org.testng.SuiteRunner.runSequentially(SuiteRunner.java:371)
at org.testng.SuiteRunner.privateRun(SuiteRunner.java:332)
at org.testng.SuiteRunner.run(SuiteRunner.java:276)
at org.testng.SuiteRunnerWorker.runSuite(SuiteRunnerWorker.java:53)
at org.testng.SuiteRunnerWorker.run(SuiteRunnerWorker.java:96)
at org.testng.TestNG.runSuitesSequentially(TestNG.java:1212)
at org.testng.TestNG.runSuitesLocally(TestNG.java:1134)
at org.testng.TestNG.runSuites(TestNG.java:1063)
at org.testng.TestNG.run(TestNG.java:1031)
at org.testng.remote.AbstractRemoteTestNG.run(AbstractRemoteTestNG.java:115)
at org.testng.remote.RemoteTestNG.initAndRun(RemoteTestNG.java:293)
at org.testng.remote.RemoteTestNG.main(RemoteTestNG.java:91)
]]>
    </failure>
  </testcase> <!-- m6 -->
  <system-out/>
  <testcase classname="TestNG.HardAssertEx" name="m12" time="0.001">
    <failure message="Im failing the TestSCript" type="java.lang.AssertionError">
      <![CDATA[java.lang.AssertionError: Im failing the TestSCript
at org.testng.Assert.fail(Assert.java:99)
at TestNG.HardAssertEx.m12(HardAssertEx.java:95)
at java.base/jdk.internal.reflect.DirectMethodHandleAccessor.invoke(DirectMethodHandleAccessor.java:103)
at java.base/java.lang.reflect.Method.invoke(Method.java:580)
at org.testng.internal.MethodInvocationHelper.invokeMethod(MethodInvocationHelper.java:133)
at org.testng.internal.TestInvoker.invokeMethod(TestInvoker.java:598)
at org.testng.internal.TestInvoker.invokeTestMethod(TestInvoker.java:173)
at org.testng.internal.MethodRunner.runInSequence(MethodRunner.java:46)
at org.testng.internal.TestInvoker$MethodInvocationAgent.invoke(TestInvoker.java:824)
at org.testng.internal.TestInvoker.invokeTestMethods(TestInvoker.java:146)
at org.testng.internal.TestMethodWorker.invokeTestMethods(TestMethodWorker.java:146)
at org.testng.internal.TestMethodWorker.run(TestMethodWorker.java:128)
at java.base/java.util.ArrayList.forEach(ArrayList.java:1596)
at org.testng.TestRunner.privateRun(TestRunner.java:794)
at org.testng.TestRunner.run(TestRunner.java:596)
at org.testng.SuiteRunner.runTest(SuiteRunner.java:377)
at org.testng.SuiteRunner.runSequentially(SuiteRunner.java:371)
at org.testng.SuiteRunner.privateRun(SuiteRunner.java:332)
at org.testng.SuiteRunner.run(SuiteRunner.java:276)
at org.testng.SuiteRunnerWorker.runSuite(SuiteRunnerWorker.java:53)
at org.testng.SuiteRunnerWorker.run(SuiteRunnerWorker.java:96)
at org.testng.TestNG.runSuitesSequentially(TestNG.java:1212)
at org.testng.TestNG.runSuitesLocally(TestNG.java:1134)
at org.testng.TestNG.runSuites(TestNG.java:1063)
at org.testng.TestNG.run(TestNG.java:1031)
at org.testng.remote.AbstractRemoteTestNG.run(AbstractRemoteTestNG.java:115)
at org.testng.remote.RemoteTestNG.initAndRun(RemoteTestNG.java:293)
at org.testng.remote.RemoteTestNG.main(RemoteTestNG.java:91)
]]>
    </failure>
  </testcase> <!-- m12 -->
  <system-out/>
  <testcase classname="TestNG.HardAssertEx" name="m10" time="0.002">
    <failure message="not same expected [hello] but found [hell]" type="java.lang.AssertionError">
      <![CDATA[java.lang.AssertionError: not same expected [hello] but found [hell]
at org.testng.Assert.fail(Assert.java:99)
at org.testng.Assert.failNotSame(Assert.java:1033)
at org.testng.Assert.assertSame(Assert.java:981)
at TestNG.HardAssertEx.m10(HardAssertEx.java:81)
at java.base/jdk.internal.reflect.DirectMethodHandleAccessor.invoke(DirectMethodHandleAccessor.java:103)
at java.base/java.lang.reflect.Method.invoke(Method.java:580)
at org.testng.internal.MethodInvocationHelper.invokeMethod(MethodInvocationHelper.java:133)
at org.testng.internal.TestInvoker.invokeMethod(TestInvoker.java:598)
at org.testng.internal.TestInvoker.invokeTestMethod(TestInvoker.java:173)
at org.testng.internal.MethodRunner.runInSequence(MethodRunner.java:46)
at org.testng.internal.TestInvoker$MethodInvocationAgent.invoke(TestInvoker.java:824)
at org.testng.internal.TestInvoker.invokeTestMethods(TestInvoker.java:146)
at org.testng.internal.TestMethodWorker.invokeTestMethods(TestMethodWorker.java:146)
at org.testng.internal.TestMethodWorker.run(TestMethodWorker.java:128)
at java.base/java.util.ArrayList.forEach(ArrayList.java:1596)
at org.testng.TestRunner.privateRun(TestRunner.java:794)
at org.testng.TestRunner.run(TestRunner.java:596)
at org.testng.SuiteRunner.runTest(SuiteRunner.java:377)
at org.testng.SuiteRunner.runSequentially(SuiteRunner.java:371)
at org.testng.SuiteRunner.privateRun(SuiteRunner.java:332)
at org.testng.SuiteRunner.run(SuiteRunner.java:276)
at org.testng.SuiteRunnerWorker.runSuite(SuiteRunnerWorker.java:53)
at org.testng.SuiteRunnerWorker.run(SuiteRunnerWorker.java:96)
at org.testng.TestNG.runSuitesSequentially(TestNG.java:1212)
at org.testng.TestNG.runSuitesLocally(TestNG.java:1134)
at org.testng.TestNG.runSuites(TestNG.java:1063)
at org.testng.TestNG.run(TestNG.java:1031)
at org.testng.remote.AbstractRemoteTestNG.run(AbstractRemoteTestNG.java:115)
at org.testng.remote.RemoteTestNG.initAndRun(RemoteTestNG.java:293)
at org.testng.remote.RemoteTestNG.main(RemoteTestNG.java:91)
]]>
    </failure>
  </testcase> <!-- m10 -->
  <system-out/>
  <testcase classname="TestNG.HardAssertEx" name="m8" time="0.001">
    <failure message="it is not Null expected [null] but found [Hello]" type="java.lang.AssertionError">
      <![CDATA[java.lang.AssertionError: it is not Null expected [null] but found [Hello]
at org.testng.Assert.fail(Assert.java:99)
at org.testng.Assert.failNotSame(Assert.java:1033)
at org.testng.Assert.assertNull(Assert.java:965)
at TestNG.HardAssertEx.m8(HardAssertEx.java:66)
at java.base/jdk.internal.reflect.DirectMethodHandleAccessor.invoke(DirectMethodHandleAccessor.java:103)
at java.base/java.lang.reflect.Method.invoke(Method.java:580)
at org.testng.internal.MethodInvocationHelper.invokeMethod(MethodInvocationHelper.java:133)
at org.testng.internal.TestInvoker.invokeMethod(TestInvoker.java:598)
at org.testng.internal.TestInvoker.invokeTestMethod(TestInvoker.java:173)
at org.testng.internal.MethodRunner.runInSequence(MethodRunner.java:46)
at org.testng.internal.TestInvoker$MethodInvocationAgent.invoke(TestInvoker.java:824)
at org.testng.internal.TestInvoker.invokeTestMethods(TestInvoker.java:146)
at org.testng.internal.TestMethodWorker.invokeTestMethods(TestMethodWorker.java:146)
at org.testng.internal.TestMethodWorker.run(TestMethodWorker.java:128)
at java.base/java.util.ArrayList.forEach(ArrayList.java:1596)
at org.testng.TestRunner.privateRun(TestRunner.java:794)
at org.testng.TestRunner.run(TestRunner.java:596)
at org.testng.SuiteRunner.runTest(SuiteRunner.java:377)
at org.testng.SuiteRunner.runSequentially(SuiteRunner.java:371)
at org.testng.SuiteRunner.privateRun(SuiteRunner.java:332)
at org.testng.SuiteRunner.run(SuiteRunner.java:276)
at org.testng.SuiteRunnerWorker.runSuite(SuiteRunnerWorker.java:53)
at org.testng.SuiteRunnerWorker.run(SuiteRunnerWorker.java:96)
at org.testng.TestNG.runSuitesSequentially(TestNG.java:1212)
at org.testng.TestNG.runSuitesLocally(TestNG.java:1134)
at org.testng.TestNG.runSuites(TestNG.java:1063)
at org.testng.TestNG.run(TestNG.java:1031)
at org.testng.remote.AbstractRemoteTestNG.run(AbstractRemoteTestNG.java:115)
at org.testng.remote.RemoteTestNG.initAndRun(RemoteTestNG.java:293)
at org.testng.remote.RemoteTestNG.main(RemoteTestNG.java:91)
]]>
    </failure>
  </testcase> <!-- m8 -->
  <system-out/>
  <testcase classname="TestNG.HardAssertEx" name="m7" time="0.001"/>
  <system-out/>
  <testcase classname="TestNG.HardAssertEx" name="m4">
    <skipped/>
  </testcase> <!-- m4 -->
  <system-out/>
</testsuite> <!-- TestNG.HardAssertEx -->
